Workbook

Sheet Cryptos
A1: ID | B1: Ticker | C1: Apertura | D1: Estado | E1: Cierre | F1: Dias | G1: Unidades | H1: Valor Compra | I1: Valor Actual | J1: Valor Venta | K1: Total Compra | L1: Total Venta | M1: Ganancias (%) | N1: Ganancias Bruta | P1: Ticker | Q1: Unidades | R1: % Cartera | S1: PPC | T1: Total (Abierto) | U1: Ganancias (%) | V1: Ganancias Tot | AC1: Crypto | AD1: USD
A2: Binance | B2: BTC | C2: 44305 | D2: CERRADA | F2: =if(B2=0,"...", IF(E2=0,today()-C2,E2-C2)) -> 1812 | G2: 0.0052924 | H2: 56496.11 | I2: =IF(B2=0,"...",IF(D2="CERRADA","-",VLOOKUP(B2,$AC$2:$AD$27,2,FALSE))) -> - | J2: =IF(B2=0,"...",IF(D2="CERRADA","Valor Venta",I2*(1-VLOOKUP(A2,Config!$B$3:$C$22,2,FALSE)))) -> Valor Venta | K2: =if(B2=0,"...",G2*H2) -> 299.00001 | L2: =IF(B2=0,"...",G2*J2) -> #VALUE! | M2: =if(B2=0,"...",L2/K2-1) -> #VALUE! | N2: =if(B2=0,"...",L2-K2) -> #VALUE! | P2: {=Unique(B10:B200)} -> BTC | Q2: =if(P2=0,"...",sumifs($G$2:$G$124,$B$2:$B$124,P2,$D$2:$D$124,"ABIERTA")) -> 0.01699 | R2: =if(P2=0,"",T2/$Y$18) -> #ERROR! | S2: =if(Q2=0,"...",if(P2=0,"...",sumifs($K$2:$K$124,$B$2:$B$124,P2,$D$2:$D$124,"ABIERTA")/Q2)) -> 65950.872 | T2: =if(P2=0,"...",sumifs($L$2:$L$124,$B$2:$B$124,P2,$D$2:$D$124,"ABIERTA")) -> 1129.1946 | U2: =if(Q2=0,"...",if(P2=0,"...",V2/(T2-V2))) -> 0.0077547571 | V2: =if(Q2=0,"...",if(P2=0,"...",sumifs($N$2:$N$124,$B$2:$B$124,P2,$D$2:$D$124,"ABIERTA"))) -> 8.6892465 | AC2: BTC | AD2: =IFERROR(__xludf.DUMMYFUNCTION("IFERROR(GOOGLEFINANCE(""CURRENCY:""&AC2&""USD""),GECKOPRICE(AC2,""USD""))"),66948.35) -> 66948.35
A3: Binance | B3: BNB | C3: 44439 | D3: ABIERTA | F3: =if(B3=0,"...", IF(E3=0,today()-C3,E3-C3)) -> 1678 | G3: 0.08891975 | H3: 562.3 | I3: =IF(B3=0,"...",IF(D3="CERRADA","-",VLOOKUP(B3,$AC$2:$AD$27,2,FALSE))) -> 593.33979 | J3: =IF(B3=0,"...",IF(D3="CERRADA","Valor Venta",I3*(1-VLOOKUP(A3,Config!$B$3:$C$22,2,FALSE)))) -> 589.03215 | K3: =if(B3=0,"...",G3*H3) -> 49.999575 | L3: =IF(B3=0,"...",G3*J3) -> 52.376591 | M3: =if(B3=0,"...",L3/K3-1) -> 0.047540721 | N3: =if(B3=0,"...",L3-K3) -> 2.3770158 | P3: DOT | Q3: =if(P3=0,"...",sumifs($G$2:$G$124,$B$2:$B$124,P3,$D$2:$D$124,"ABIERTA")) -> 24.63 | R3: =if(P3=0,"",T3/$Y$18) -> #ERROR! | S3: =if(Q3=0,"...",if(P3=0,"...",sumifs($K$2:$K$124,$B$2:$B$124,P3,$D$2:$D$124,"ABIERTA")/Q3)) -> 4.208 | T3: =if(P3=0,"...",sumifs($L$2:$L$124,$B$2:$B$124,P3,$D$2:$D$124,"ABIERTA")) -> 30.006496 | U3: =if(Q3=0,"...",if(P3=0,"...",V3/(T3-V3))) -> -0.71048229 | V3: =if(Q3=0,"...",if(P3=0,"...",sumifs($N$2:$N$124,$B$2:$B$124,P3,$D$2:$D$124,"ABIERTA"))) -> -73.636544 | AC3: BNB | AD3: =IFERROR(__xludf.DUMMYFUNCTION("IFERROR(GOOGLEFINANCE(""CURRENCY:""&AC3&""USD""),GECKOPRICE(AC3,""USD""))"),593.3397941) -> 593.33979
A4: Binance | B4: AVAX | C4: 44529 | D4: CERRADA | F4: =if(B4=0,"...", IF(E4=0,today()-C4,E4-C4)) -> 1588 | G4: 0.42 | H4: 119.05 | I4: =IF(B4=0,"...",IF(D4="CERRADA","-",VLOOKUP(B4,$AC$2:$AD$27,2,FALSE))) -> - | J4: 33.62 | K4: =if(B4=0,"...",G4*H4) -> 50.001 | L4: =IF(B4=0,"...",G4*J4) -> 14.1204 | M4: =if(B4=0,"...",L4/K4-1) -> -0.71759765 | N4: =if(B4=0,"...",L4-K4) -> -35.8806 | P4: SOL | Q4: =if(P4=0,"...",sumifs($G$2:$G$124,$B$2:$B$124,P4,$D$2:$D$124,"ABIERTA")) -> 9.646 | R4: =if(P4=0,"",T4/$Y$18) -> #ERROR! | S4: =if(Q4=0,"...",if(P4=0,"...",sumifs($K$2:$K$124,$B$2:$B$124,P4,$D$2:$D$124,"ABIERTA")/Q4)) -> 154.17525 | T4: =if(P4=0,"...",sumifs($L$2:$L$124,$B$2:$B$124,P4,$D$2:$D$124,"ABIERTA")) -> 764.22082 | U4: =if(Q4=0,"...",if(P4=0,"...",V4/(T4-V4))) -> -0.48612563 | V4: =if(Q4=0,"...",if(P4=0,"...",sumifs($N$2:$N$124,$B$2:$B$124,P4,$D$2:$D$124,"ABIERTA"))) -> -722.95361 | AC4: AVAX
A5: Binance | B5: BTC | C5: 44530 | D5: CERRADA | F5: =if(B5=0,"...", IF(E5=0,today()-C5,E5-C5)) -> 1587 | G5: 0.00173 | H5: 48000 | I5: =IF(B5=0,"...",IF(D5="CERRADA","-",VLOOKUP(B5,$AC$2:$AD$27,2,FALSE))) -> - | J5: =IF(B5=0,"...",IF(D5="CERRADA","Valor Venta",I5*(1-VLOOKUP(A5,Config!$B$3:$C$22,2,FALSE)))) -> Valor Venta | K5: =if(B5=0,"...",G5*H5) -> 83.04 | L5: =IF(B5=0,"...",G5*J5) -> #VALUE! | M5: =if(B5=0,"...",L5/K5-1) -> #VALUE! | N5: =if(B5=0,"...",L5-K5) -> #VALUE! | P5: RUNE | Q5: =if(P5=0,"...",sumifs($G$2:$G$124,$B$2:$B$124,P5,$D$2:$D$124,"ABIERTA")) -> 0 | R5: =if(P5=0,"",T5/$Y$18) -> #ERROR! | S5: =if(Q5=0,"...",if(P5=0,"...",sumifs($K$2:$K$124,$B$2:$B$124,P5,$D$2:$D$124,"ABIERTA")/Q5)) -> ... | T5: =if(P5=0,"...",sumifs($L$2:$L$124,$B$2:$B$124,P5,$D$2:$D$124,"ABIERTA")) -> 0 | U5: =if(Q5=0,"...",if(P5=0,"...",V5/(T5-V5))) -> ... | V5: =if(Q5=0,"...",if(P5=0,"...",sumifs($N$2:$N$124,$B$2:$B$124,P5,$D$2:$D$124,"ABIERTA"))) -> ... | AC5: ETH | AD5: =IFERROR(__xludf.DUMMYFUNCTION("IFERROR(GOOGLEFINANCE(""CURRENCY:""&AC5&""USD""),GECKOPRICE(AC5,""USD""))"),2039.8307000000002) -> 2039.8307
A6: Binance | B6: ETH | C6: 44577 | D6: CERRADA | F6: =if(B6=0,"...", IF(E6=0,today()-C6,E6-C6)) -> 1540 | G6: 0.0173 | H6: 3352.6 | I6: =IF(B6=0,"...",IF(D6="CERRADA","-",VLOOKUP(B6,$AC$2:$AD$27,2,FALSE))) -> - | J6: 2744 | K6: =if(B6=0,"...",G6*H6) -> 57.99998 | L6: =IF(B6=0,"...",G6*J6) -> 47.4712 | M6: =if(B6=0,"...",L6/K6-1) -> -0.18153075 | N6: =if(B6=0,"...",L6-K6) -> -10.52878 | P6: MATIC | Q6: =if(P6=0,"...",sumifs($G$2:$G$124,$B$2:$B$124,P6,$D$2:$D$124,"ABIERTA")) -> 0 | R6: =if(P6=0,"",T6/$Y$18) -> #ERROR! | S6: =if(Q6=0,"...",if(P6=0,"...",sumifs($K$2:$K$124,$B$2:$B$124,P6,$D$2:$D$124,"ABIERTA")/Q6)) -> ... | T6: =if(P6=0,"...",sumifs($L$2:$L$124,$B$2:$B$124,P6,$D$2:$D$124,"ABIERTA")) -> 0 | U6: =if(Q6=0,"...",if(P6=0,"...",V6/(T6-V6))) -> ... | V6: =if(Q6=0,"...",if(P6=0,"...",sumifs($N$2:$N$124,$B$2:$B$124,P6,$D$2:$D$124,"ABIERTA"))) -> ... | AC6: DOT | AD6: =IFERROR(__xludf.DUMMYFUNCTION("IFERROR(GOOGLEFINANCE(""CURRENCY:""&AC6&""USD""),GECKOPRICE(AC6,""USD""))"),1.2272) -> 1.2272
A7: Binance | B7: BTC | C7: 44676 | D7: CERRADA | F7: =if(B7=0,"...", IF(E7=0,today()-C7,E7-C7)) -> 1441 | G7: 0.003532468 | H7: 38500 | I7: =IF(B7=0,"...",IF(D7="CERRADA","-",VLOOKUP(B7,$AC$2:$AD$27,2,FALSE))) -> - | J7: =IF(B7=0,"...",IF(D7="CERRADA","Valor Venta",I7*(1-VLOOKUP(A7,Config!$B$3:$C$22,2,FALSE)))) -> Valor Venta | K7: =if(B7=0,"...",G7*H7) -> 136.00002 | L7: =IF(B7=0,"...",G7*J7) -> #VALUE! | M7: =if(B7=0,"...",L7/K7-1) -> #VALUE! | N7: =if(B7=0,"...",L7-K7) -> #VALUE! | P7: ADA | Q7: =if(P7=0,"...",sumifs($G$2:$G$124,$B$2:$B$124,P7,$D$2:$D$124,"ABIERTA")) -> 0 | R7: =if(P7=0,"",T7/$Y$18) -> #ERROR! | S7: =if(Q7=0,"...",if(P7=0,"...",sumifs($K$2:$K$124,$B$2:$B$124,P7,$D$2:$D$124,"ABIERTA")/Q7)) -> ... | T7: =if(P7=0,"...",sumifs($L$2:$L$124,$B$2:$B$124,P7,$D$2:$D$124,"ABIERTA")) -> 0 | U7: =if(Q7=0,"...",if(P7=0,"...",V7/(T7-V7))) -> ... | V7: =if(Q7=0,"...",if(P7=0,"...",sumifs($N$2:$N$124,$B$2:$B$124,P7,$D$2:$D$124,"ABIERTA"))) -> ... | AC7: SOL | AD7: =IFERROR(__xludf.DUMMYFUNCTION("IFERROR(GOOGLEFINANCE(""CURRENCY:""&AC7&""USD""),GECKOPRICE(AC7,""USD""))"),79.8061) -> 79.8061
A8: Binance | B8: BTC | C8: 44689 | D8: CERRADA | F8: =if(B8=0,"...", IF(E8=0,today()-C8,E8-C8)) -> 1428 | G8: 0.005571031 | H8: 35900 | I8: =IF(B8=0,"...",IF(D8="CERRADA","-",VLOOKUP(B8,$AC$2:$AD$27,2,FALSE))) -> - | J8: =IF(B8=0,"...",IF(D8="CERRADA","Valor Venta",I8*(1-VLOOKUP(A8,Config!$B$3:$C$22,2,FALSE)))) -> Valor Venta | K8: =if(B8=0,"...",G8*H8) -> 200.00001 | L8: =IF(B8=0,"...",G8*J8) -> #VALUE! | M8: =if(B8=0,"...",L8/K8-1) -> #VALUE! | N8: =if(B8=0,"...",L8-K8) -> #VALUE! | P8: XTZ | Q8: =if(P8=0,"...",sumifs($G$2:$G$124,$B$2:$B$124,P8,$D$2:$D$124,"ABIERTA")) -> 0 | R8: =if(P8=0,"",T8/$Y$18) -> #ERROR! | S8: =if(Q8=0,"...",if(P8=0,"...",sumifs($K$2:$K$124,$B$2:$B$124,P8,$D$2:$D$124,"ABIERTA")/Q8)) -> ... | T8: =if(P8=0,"...",sumifs($L$2:$L$124,$B$2:$B$124,P8,$D$2:$D$124,"ABIERTA")) -> 0 | U8: =if(Q8=0,"...",if(P8=0,"...",V8/(T8-V8))) -> ... | V8: =if(Q8=0,"...",if(P8=0,"...",sumifs($N$2:$N$124,$B$2:$B$124,P8,$D$2:$D$124,"ABIERTA"))) -> ... | AC8: RUNE
A9: Binance | B9: BTC | C9: 45037 | D9: CERRADA | F9: =if(B9=0,"...", IF(E9=0,today()-C9,E9-C9)) -> 1080 | G9: 0.010690122 | H9: 28082 | I9: =IF(B9=0,"...",IF(D9="CERRADA","-",VLOOKUP(B9,$AC$2:$AD$27,2,FALSE))) -> - | J9: =IF(B9=0,"...",IF(D9="CERRADA","Valor Venta",I9*(1-VLOOKUP(A9,Config!$B$3:$C$22,2,FALSE)))) -> Valor Venta | K9: =if(B9=0,"...",G9*H9) -> 300.20001 | L9: =IF(B9=0,"...",G9*J9) -> #VALUE! | M9: =if(B9=0,"...",L9/K9-1) -> #VALUE! | N9: =if(B9=0,"...",L9-K9) -> #VALUE! | P9: SAND | Q9: =if(P9=0,"...",sumifs($G$2:$G$124,$B$2:$B$124,P9,$D$2:$D$124,"ABIERTA")) -> 0 | R9: =if(P9=0,"",T9/$Y$18) -> #ERROR! | S9: =if(Q9=0,"...",if(P9=0,"...",sumifs($K$2:$K$124,$B$2:$B$124,P9,$D$2:$D$124,"ABIERTA")/Q9)) -> ... | T9: =if(P9=0,"...",sumifs($L$2:$L$124,$B$2:$B$124,P9,$D$2:$D$124,"ABIERTA")) -> 0 | U9: =if(Q9=0,"...",if(P9=0,"...",V9/(T9-V9))) -> ... | V9: =if(Q9=0,"...",if(P9=0,"...",sumifs($N$2:$N$124,$B$2:$B$124,P9,$D$2:$D$124,"ABIERTA"))) -> ... | AC9: MATIC
A10: Binance | B10: BTC | C10: 45123 | D10: CERRADA | F10: =if(B10=0,"...", IF(E10=0,today()-C10,E10-C10)) -> 994 | G10: 0.011229977 | H10: 30277 | I10: =IF(B10=0,"...",IF(D10="CERRADA","-",VLOOKUP(B10,$AC$2:$AD$27,2,FALSE))) -> - | J10: =IF(B10=0,"...",IF(D10="CERRADA","Valor Venta",I10*(1-VLOOKUP(A10,Config!$B$3:$C$22,2,FALSE)))) -> Valor Venta | K10: =if(B10=0,"...",G10*H10) -> 340.01001 | L10: =IF(B10=0,"...",G10*J10) -> #VALUE! | M10: =if(B10=0,"...",L10/K10-1) -> #VALUE! | N10: =if(B10=0,"...",L10-K10) -> #VALUE! | P10: CRV | Q10: =if(P10=0,"...",sumifs($G$2:$G$124,$B$2:$B$124,P10,$D$2:$D$124,"ABIERTA")) -> 0 | R10: =if(P10=0,"",T10/$Y$18) -> #ERROR! | S10: =if(Q10=0,"...",if(P10=0,"...",sumifs($K$2:$K$124,$B$2:$B$124,P10,$D$2:$D$124,"ABIERTA")/Q10)) -> ... | T10: =if(P10=0,"...",sumifs($L$2:$L$124,$B$2:$B$124,P10,$D$2:$D$124,"ABIERTA")) -> 0 | U10: =if(Q10=0,"...",if(P10=0,"...",V10/(T10-V10))) -> ... | V10: =if(Q10=0,"...",if(P10=0,"...",sumifs($N$2:$N$124,$B$2:$B$124,P10,$D$2:$D$124,"ABIERTA"))) -> ... | AC10: UNI
A11: Binance | B11: BTC | C11: 45180 | D11: CERRADA | F11: =if(B11=0,"...", IF(E11=0,today()-C11,E11-C11)) -> 937 | G11: 0.004909613 | H11: 25148.62 | I11: =IF(B11=0,"...",IF(D11="CERRADA","-",VLOOKUP(B11,$AC$2:$AD$27,2,FALSE))) -> - | J11: =IF(B11=0,"...",IF(D11="CERRADA","Valor Venta",I11*(1-VLOOKUP(A11,Config!$B$3:$C$22,2,FALSE)))) -> Valor Venta | K11: =if(B11=0,"...",G11*H11) -> 123.46999 | L11: =IF(B11=0,"...",G11*J11) -> #VALUE! | M11: =if(B11=0,"...",L11/K11-1) -> #VALUE! | N11: =if(B11=0,"...",L11-K11) -> #VALUE! | P11: MANA | Q11: =if(P11=0,"...",sumifs($G$2:$G$124,$B$2:$B$124,P11,$D$2:$D$124,"ABIERTA")) -> 0 | R11: =if(P11=0,"",T11/$Y$18) -> #ERROR! | S11: =if(Q11=0,"...",if(P11=0,"...",sumifs($K$2:$K$124,$B$2:$B$124,P11,$D$2:$D$124,"ABIERTA")/Q11)) -> ... | T11: =if(P11=0,"...",sumifs($L$2:$L$124,$B$2:$B$124,P11,$D$2:$D$124,"ABIERTA")) -> 0 | U11: =if(Q11=0,"...",if(P11=0,"...",V11/(T11-V11))) -> ... | V11: =if(Q11=0,"...",if(P11=0,"...",sumifs($N$2:$N$124,$B$2:$B$124,P11,$D$2:$D$124,"ABIERTA"))) -> ... | AC11: SAND
A12: Binance | B12: DOT | C12: 45204 | D12: CERRADA | E12: 45265 | F12: =if(B12=0,"...", IF(E12=0,today()-C12,E12-C12)) -> 61 | G12: 4.9788399 | H12: 4.02 | I12: =IF(B12=0,"...",IF(D12="CERRADA","-",VLOOKUP(B12,$AC$2:$AD$27,2,FALSE))) -> - | J12: 5.77 | K12: =if(B12=0,"...",G12*H12) -> 20.014937 | L12: =IF(B12=0,"...",G12*J12) -> 28.727906 | M12: =if(B12=0,"...",L12/K12-1) -> 0.43532338 | N12: =if(B12=0,"...",L12-K12) -> 8.7129699 | P12: 1INCH | Q12: =if(P12=0,"...",sumifs($G$2:$G$124,$B$2:$B$124,P12,$D$2:$D$124,"ABIERTA")) -> 0 | R12: =if(P12=0,"",T12/$Y$18) -> #ERROR! | S12: =if(Q12=0,"...",if(P12=0,"...",sumifs($K$2:$K$124,$B$2:$B$124,P12,$D$2:$D$124,"ABIERTA")/Q12)) -> ... | T12: =if(P12=0,"...",sumifs($L$2:$L$124,$B$2:$B$124,P12,$D$2:$D$124,"ABIERTA")) -> 0 | U12: =if(Q12=0,"...",if(P12=0,"...",V12/(T12-V12))) -> ... | V12: =if(Q12=0,"...",if(P12=0,"...",sumifs($N$2:$N$124,$B$2:$B$124,P12,$D$2:$D$124,"ABIERTA"))) -> ... | AC12: SAND
A13: Binance | B13: BTC | C13: 45204 | D13: CERRADA | F13: =if(B13=0,"...", IF(E13=0,today()-C13,E13-C13)) -> 913 | G13: 0.002669717 | H13: 27482.31 | I13: =IF(B13=0,"...",IF(D13="CERRADA","-",VLOOKUP(B13,$AC$2:$AD$27,2,FALSE))) -> - | J13: =IF(B13=0,"...",IF(D13="CERRADA","Valor Venta",I13*(1-VLOOKUP(A13,Config!$B$3:$C$22,2,FALSE)))) -> Valor Venta | K13: =if(B13=0,"...",G13*H13) -> 73.36999 | L13: =IF(B13=0,"...",G13*J13) -> #VALUE! | M13: =if(B13=0,"...",L13/K13-1) -> #VALUE! | N13: =if(B13=0,"...",L13-K13) -> #VALUE! | P13: NEAR | Q13: =if(P13=0,"...",sumifs($G$2:$G$124,$B$2:$B$124,P13,$D$2:$D$124,"ABIERTA")) -> 0 | R13: =if(P13=0,"",T13/$Y$18) -> #ERROR! | S13: =if(Q13=0,"...",if(P13=0,"...",sumifs($K$2:$K$124,$B$2:$B$124,P13,$D$2:$D$124,"ABIERTA")/Q13)) -> ... | T13: =if(P13=0,"...",sumifs($L$2:$L$124,$B$2:$B$124,P13,$D$2:$D$124,"ABIERTA")) -> 0 | U13: =if(Q13=0,"...",if(P13=0,"...",V13/(T13-V13))) -> ... | V13: =if(Q13=0,"...",if(P13=0,"...",sumifs($N$2:$N$124,$B$2:$B$124,P13,$D$2:$D$124,"ABIERTA"))) -> ... | AC13: ONE
A14: Binance | B14: BTC | C14: 45236 | D14: CERRADA | F14: =if(B14=0,"...", IF(E14=0,today()-C14,E14-C14)) -> 881 | G14: 0.002873563 | H14: 34800 | I14: =IF(B14=0,"...",IF(D14="CERRADA","-",VLOOKUP(B14,$AC$2:$AD$27,2,FALSE))) -> - | J14: =IF(B14=0,"...",IF(D14="CERRADA","Valor Venta",I14*(1-VLOOKUP(A14,Config!$B$3:$C$22,2,FALSE)))) -> Valor Venta | K14: =if(B14=0,"...",G14*H14) -> 99.999992 | L14: =IF(B14=0,"...",G14*J14) -> #VALUE! | M14: =if(B14=0,"...",L14/K14-1) -> #VALUE! | N14: =if(B14=0,"...",L14-K14) -> #VALUE! | P14: GALA | Q14: =if(P14=0,"...",sumifs($G$2:$G$124,$B$2:$B$124,P14,$D$2:$D$124,"ABIERTA")) -> 0 | R14: =if(P14=0,"",T14/$Y$18) -> #ERROR! | S14: =if(Q14=0,"...",if(P14=0,"...",sumifs($K$2:$K$124,$B$2:$B$124,P14,$D$2:$D$124,"ABIERTA")/Q14)) -> ... | T14: =if(P14=0,"...",sumifs($L$2:$L$124,$B$2:$B$124,P14,$D$2:$D$124,"ABIERTA")) -> 0 | U14: =if(Q14=0,"...",if(P14=0,"...",V14/(T14-V14))) -> ... | V14: =if(Q14=0,"...",if(P14=0,"...",sumifs($N$2:$N$124,$B$2:$B$124,P14,$D$2:$D$124,"ABIERTA"))) -> ... | AC14: RNDR
A15: Binance | B15: DOT | C15: 45236 | D15: CERRADA | E15: 45265 | F15: =if(B15=0,"...", IF(E15=0,today()-C15,E15-C15)) -> 29 | G15: 4.338843 | H15: 4.84 | I15: =IF(B15=0,"...",IF(D15="CERRADA","-",VLOOKUP(B15,$AC$2:$AD$27,2,FALSE))) -> - | J15: 5.77 | K15: =if(B15=0,"...",G15*H15) -> 21 | L15: =IF(B15=0,"...",G15*J15) -> 25.035124 | M15: =if(B15=0,"...",L15/K15-1) -> 0.19214876 | N15: =if(B15=0,"...",L15-K15) -> 4.035124 | P15: KSM | Q15: =if(P15=0,"...",sumifs($G$2:$G$124,$B$2:$B$124,P15,$D$2:$D$124,"ABIERTA")) -> 0 | R15: =if(P15=0,"",T15/$Y$18) -> #ERROR! | S15: =if(Q15=0,"...",if(P15=0,"...",sumifs($K$2:$K$124,$B$2:$B$124,P15,$D$2:$D$124,"ABIERTA")/Q15)) -> ... | T15: =if(P15=0,"...",sumifs($L$2:$L$124,$B$2:$B$124,P15,$D$2:$D$124,"ABIERTA")) -> 0 | U15: =if(Q15=0,"...",if(P15=0,"...",V15/(T15-V15))) -> ... | V15: =if(Q15=0,"...",if(P15=0,"...",sumifs($N$2:$N$124,$B$2:$B$124,P15,$D$2:$D$124,"ABIERTA"))) -> ... | AC15: 1INCH
A16: Binance | B16: BTC | C16: 45246 | D16: CERRADA | F16: =if(B16=0,"...", IF(E16=0,today()-C16,E16-C16)) -> 871 | G16: 0.00273 | H16: 36630.04 | I16: =IF(B16=0,"...",IF(D16="CERRADA","-",VLOOKUP(B16,$AC$2:$AD$27,2,FALSE))) -> - | J16: =IF(B16=0,"...",IF(D16="CERRADA","Valor Venta",I16*(1-VLOOKUP(A16,Config!$B$3:$C$22,2,FALSE)))) -> Valor Venta | K16: =if(B16=0,"...",G16*H16) -> 100.00001 | L16: =IF(B16=0,"...",G16*J16) -> #VALUE! | M16: =if(B16=0,"...",L16/K16-1) -> #VALUE! | N16: =if(B16=0,"...",L16-K16) -> #VALUE! | P16: SEI | Q16: =if(P16=0,"...",sumifs($G$2:$G$124,$B$2:$B$124,P16,$D$2:$D$124,"ABIERTA")) -> 0 | R16: =if(P16=0,"",T16/$Y$18) -> #ERROR! | S16: =if(Q16=0,"...",if(P16=0,"...",sumifs($K$2:$K$124,$B$2:$B$124,P16,$D$2:$D$124,"ABIERTA")/Q16)) -> ... | T16: =if(P16=0,"...",sumifs($L$2:$L$124,$B$2:$B$124,P16,$D$2:$D$124,"ABIERTA")) -> 0 | U16: =if(Q16=0,"...",if(P16=0,"...",V16/(T16-V16))) -> ... | V16: =if(Q16=0,"...",if(P16=0,"...",sumifs($N$2:$N$124,$B$2:$B$124,P16,$D$2:$D$124,"ABIERTA"))) -> ... | AC16: RONIN
A17: Binance | B17: SOL | C17: 45254 | D17: CERRADA | E17: 45263 | F17: =if(B17=0,"...", IF(E17=0,today()-C17,E17-C17)) -> 9 | G17: 0.79 | H17: 58.06 | I17: =IF(B17=0,"...",IF(D17="CERRADA","-",VLOOKUP(B17,$AC$2:$AD$27,2,FALSE))) -> - | J17: 64.15 | K17: =if(B17=0,"...",G17*H17) -> 45.8674 | L17: =IF(B17=0,"...",G17*J17) -> 50.6785 | M17: =if(B17=0,"...",L17/K17-1) -> 0.10489149 | N17: =if(B17=0,"...",L17-K17) -> 4.8111 | P17: LINK | Q17: =if(P17=0,"...",sumifs($G$2:$G$124,$B$2:$B$124,P17,$D$2:$D$124,"ABIERTA")) -> 0 | R17: =if(P17=0,"",T17/$Y$18) -> #ERROR! | S17: =if(Q17=0,"...",if(P17=0,"...",sumifs($K$2:$K$124,$B$2:$B$124,P17,$D$2:$D$124,"ABIERTA")/Q17)) -> ... | T17: =if(P17=0,"...",sumifs($L$2:$L$124,$B$2:$B$124,P17,$D$2:$D$124,"ABIERTA")) -> 0 | U17: =if(Q17=0,"...",if(P17=0,"...",V17/(T17-V17))) -> ... | V17: =if(Q17=0,"...",if(P17=0,"...",sumifs($N$2:$N$124,$B$2:$B$124,P17,$D$2:$D$124,"ABIERTA"))) -> ... | AC17: GALA
A18: Binance | B18: SOL | C18: 45254 | D18: CERRADA | E18: 45263 | F18: =if(B18=0,"...", IF(E18=0,today()-C18,E18-C18)) -> 9 | G18: 0.77 | H18: 58.16 | I18: =IF(B18=0,"...",IF(D18="CERRADA","-",VLOOKUP(B18,$AC$2:$AD$27,2,FALSE))) -> - | J18: 64.15 | K18: =if(B18=0,"...",G18*H18) -> 44.7832 | L18: =IF(B18=0,"...",G18*J18) -> 49.3955 | M18: =if(B18=0,"...",L18/K18-1) -> 0.10299175 | N18: =if(B18=0,"...",L18-K18) -> 4.6123 | P18: AVAX | Q18: =if(P18=0,"...",sumifs($G$2:$G$124,$B$2:$B$124,P18,$D$2:$D$124,"ABIERTA")) -> 0 | R18: =if(P18=0,"",T18/$Y$18) -> #ERROR! | S18: =if(Q18=0,"...",if(P18=0,"...",sumifs($K$2:$K$124,$B$2:$B$124,P18,$D$2:$D$124,"ABIERTA")/Q18)) -> ... | T18: =if(P18=0,"...",sumifs($L$2:$L$124,$B$2:$B$124,P18,$D$2:$D$124,"ABIERTA")) -> 0 | U18: =if(Q18=0,"...",if(P18=0,"...",V18/(T18-V18))) -> ... | V18: =if(Q18=0,"...",if(P18=0,"...",sumifs($N$2:$N$124,$B$2:$B$124,P18,$D$2:$D$124,"ABIERTA"))) -> ... | X18: Tenencias Actuales | Y18: =SUMIFS(L2:L150,D2:D150,"ABIERTA") -> #ERROR! | Z18: Total Acumulado | AA18: =SUM(L2:L150) -> #VALUE! | AC18: KSM
A19: Binance | B19: RUNE | C19: 45264 | D19: CERRADA | E19: 45268 | F19: =if(B19=0,"...", IF(E19=0,today()-C19,E19-C19)) -> 4 | G19: 13.2 | H19: 6.75 | I19: =IF(B19=0,"...",IF(D19="CERRADA","-",VLOOKUP(B19,$AC$2:$AD$27,2,FALSE))) -> - | J19: 6.6 | K19: =if(B19=0,"...",G19*H19) -> 89.1 | L19: =IF(B19=0,"...",G19*J19) -> 87.12 | M19: =if(B19=0,"...",L19/K19-1) -> -0.022222222 | N19: =if(B19=0,"...",L19-K19) -> -1.98 | P19: SHIB | Q19: =if(P19=0,"...",sumifs($G$2:$G$124,$B$2:$B$124,P19,$D$2:$D$124,"ABIERTA")) -> 0 | R19: =if(P19=0,"",T19/$Y$18) -> #ERROR! | S19: =if(Q19=0,"...",if(P19=0,"...",sumifs($K$2:$K$124,$B$2:$B$124,P19,$D$2:$D$124,"ABIERTA")/Q19)) -> ... | T19: =if(P19=0,"...",sumifs($L$2:$L$124,$B$2:$B$124,P19,$D$2:$D$124,"ABIERTA")) -> 0 | U19: =if(Q19=0,"...",if(P19=0,"...",V19/(T19-V19))) -> ... | V19: =if(Q19=0,"...",if(P19=0,"...",sumifs($N$2:$N$124,$B$2:$B$124,P19,$D$2:$D$124,"ABIERTA"))) -> ... | AC19: SEI
A20: Binance | B20: MATIC | C20: 45268 | D20: CERRADA | F20: =if(B20=0,"...", IF(E20=0,today()-C20,E20-C20)) -> 849 | G20: 44.4 | H20: 0.9 | I20: =IF(B20=0,"...",IF(D20="CERRADA","-",VLOOKUP(B20,$AC$2:$AD$27,2,FALSE))) -> - | J20: 0.9 | K20: =if(B20=0,"...",G20*H20) -> 39.96 | L20: =IF(B20=0,"...",G20*J20) -> 39.96 | M20: =if(B20=0,"...",L20/K20-1) -> 0 | N20: =if(B20=0,"...",L20-K20) -> 0 | P20: RNDR | Q20: =if(P20=0,"...",sumifs($G$2:$G$124,$B$2:$B$124,P20,$D$2:$D$124,"ABIERTA")) -> 0 | R20: =if(P20=0,"",T20/$Y$18) -> #ERROR! | S20: =if(Q20=0,"...",if(P20=0,"...",sumifs($K$2:$K$124,$B$2:$B$124,P20,$D$2:$D$124,"ABIERTA")/Q20)) -> ... | T20: =if(P20=0,"...",sumifs($L$2:$L$124,$B$2:$B$124,P20,$D$2:$D$124,"ABIERTA")) -> 0 | U20: =if(Q20=0,"...",if(P20=0,"...",V20/(T20-V20))) -> ... | V20: =if(Q20=0,"...",if(P20=0,"...",sumifs($N$2:$N$124,$B$2:$B$124,P20,$D$2:$D$124,"ABIERTA"))) -> ... | X20: Ganancia Abierto | Y20: =SUMIFS(N2:N150,D2:D150,"ABIERTA") -> #ERROR! | Z20: Ganancia Acumulada | AA20: =SUM(N2:N150) -> #VALUE! | AC20: LINK
A21: Binance | B21: DOT | C21: 45268 | D21: CERRADA | F21: =if(B21=0,"...", IF(E21=0,today()-C21,E21-C21)) -> 849 | G21: 5.97 | H21: 6.7 | I21: =IF(B21=0,"...",IF(D21="CERRADA","-",VLOOKUP(B21,$AC$2:$AD$27,2,FALSE))) -> - | J21: 5.77 | K21: =if(B21=0,"...",G21*H21) -> 39.999 | L21: =IF(B21=0,"...",G21*J21) -> 34.4469 | M21: =if(B21=0,"...",L21/K21-1) -> -0.13880597 | N21: =if(B21=0,"...",L21-K21) -> -5.5521 | P21: AAVE | Q21: =if(P21=0,"...",sumifs($G$2:$G$124,$B$2:$B$124,P21,$D$2:$D$124,"ABIERTA")) -> 0.305 | R21: =if(P21=0,"",T21/$Y$18) -> #ERROR! | S21: =if(Q21=0,"...",if(P21=0,"...",sumifs($K$2:$K$124,$B$2:$B$124,P21,$D$2:$D$124,"ABIERTA")/Q21)) -> 331.2 | T21: =if(P21=0,"...",sumifs($L$2:$L$124,$B$2:$B$124,P21,$D$2:$D$124,"ABIERTA")) -> #ERROR! | U21: =if(Q21=0,"...",if(P21=0,"...",V21/(T21-V21))) -> #ERROR! | V21: =if(Q21=0,"...",if(P21=0,"...",sumifs($N$2:$N$124,$B$2:$B$124,P21,$D$2:$D$124,"ABIERTA"))) -> #ERROR! | AC21: SHIB
A22: Binance | B22: SOL | C22: 45268 | D22: CERRADA | E22: 45282 | F22: =if(B22=0,"...", IF(E22=0,today()-C22,E22-C22)) -> 14 | G22: 0.54 | H22: 73.22 | I22: =IF(B22=0,"...",IF(D22="CERRADA","-",VLOOKUP(B22,$AC$2:$AD$27,2,FALSE))) -> - | J22: 97 | K22: =if(B22=0,"...",G22*H22) -> 39.5388 | L22: =IF(B22=0,"...",G22*J22) -> 52.38 | M22: =if(B22=0,"...",L22/K22-1) -> 0.32477465 | N22: =if(B22=0,"...",L22-K22) -> 12.8412 | P22: TRX | Q22: =if(P22=0,"...",sumifs($G$2:$G$124,$B$2:$B$124,P22,$D$2:$D$124,"ABIERTA")) -> 316.1 | R22: =if(P22=0,"",T22/$Y$18) -> #ERROR! | S22: =if(Q22=0,"...",if(P22=0,"...",sumifs($K$2:$K$124,$B$2:$B$124,P22,$D$2:$D$124,"ABIERTA")/Q22)) -> 0.3163 | T22: =if(P22=0,"...",sumifs($L$2:$L$124,$B$2:$B$124,P22,$D$2:$D$124,"ABIERTA")) -> 99.699964 | U22: =if(Q22=0,"...",if(P22=0,"...",V22/(T22-V22))) -> -0.0028251545 | V22: =if(Q22=0,"...",if(P22=0,"...",sumifs($N$2:$N$124,$B$2:$B$124,P22,$D$2:$D$124,"ABIERTA"))) -> -0.28246582 | X22: (%) | Y22: =Y20/(Y18-Y20) -> #ERROR! | Z22: (%) | AA22: =AA20/(AA18-AA20) -> #VALUE! | AC22: RNDR
A23: Binance | B23: ADA | C23: 45269 | D23: CERRADA | F23: =if(B23=0,"...", IF(E23=0,today()-C23,E23-C23)) -> 848 | G23: 32.9 | H23: 0.61 | I23: =IF(B23=0,"...",IF(D23="CERRADA","-",VLOOKUP(B23,$AC$2:$AD$27,2,FALSE))) -> - | J23: 0.7614 | K23: =if(B23=0,"...",G23*H23) -> 20.069 | L23: =IF(B23=0,"...",G23*J23) -> 25.05006 | M23: =if(B23=0,"...",L23/K23-1) -> 0.24819672 | N23: =if(B23=0,"...",L23-K23) -> 4.98106 | P23: UNI | Q23: =if(P23=0,"...",sumifs($G$2:$G$124,$B$2:$B$124,P23,$D$2:$D$124,"ABIERTA")) -> 8.52 | R23: =if(P23=0,"",T23/$Y$18) -> #ERROR! | S23: =if(Q23=0,"...",if(P23=0,"...",sumifs($K$2:$K$124,$B$2:$B$124,P23,$D$2:$D$124,"ABIERTA")/Q23)) -> 10.547 | T23: =if(P23=0,"...",sumifs($L$2:$L$124,$B$2:$B$124,P23,$D$2:$D$124,"ABIERTA")) -> 0 | U23: =if(Q23=0,"...",if(P23=0,"...",V23/(T23-V23))) -> -1 | V23: =if(Q23=0,"...",if(P23=0,"...",sumifs($N$2:$N$124,$B$2:$B$124,P23,$D$2:$D$124,"ABIERTA"))) -> -89.86044 | AC23: AAVE | AD23: =IFERROR(__xludf.DUMMYFUNCTION("IFERROR(GOOGLEFINANCE(""CURRENCY:""&AC23&""USDT""),GECKOPRICE(AC23,""USD""))"),"#ERROR!") -> #ERROR!
A24: Binance | B24: ADA | C24: 45271 | D24: CERRADA | F24: =if(B24=0,"...", IF(E24=0,today()-C24,E24-C24)) -> 846 | G24: 35.5 | H24: 0.56 | I24: =IF(B24=0,"...",IF(D24="CERRADA","-",VLOOKUP(B24,$AC$2:$AD$27,2,FALSE))) -> - | J24: 0.7614 | K24: =if(B24=0,"...",G24*H24) -> 19.88 | L24: =IF(B24=0,"...",G24*J24) -> 27.0297 | M24: =if(B24=0,"...",L24/K24-1) -> 0.35964286 | N24: =if(B24=0,"...",L24-K24) -> 7.1497 | P24: DOGE | Q24: =if(P24=0,"...",sumifs($G$2:$G$124,$B$2:$B$124,P24,$D$2:$D$124,"ABIERTA")) -> 0 | R24: =if(P24=0,"",T24/$Y$18) -> #ERROR! | S24: =if(Q24=0,"...",if(P24=0,"...",sumifs($K$2:$K$124,$B$2:$B$124,P24,$D$2:$D$124,"ABIERTA")/Q24)) -> ... | T24: =if(P24=0,"...",sumifs($L$2:$L$124,$B$2:$B$124,P24,$D$2:$D$124,"ABIERTA")) -> 0 | U24: =if(Q24=0,"...",if(P24=0,"...",V24/(T24-V24))) -> ... | V24: =if(Q24=0,"...",if(P24=0,"...",sumifs($N$2:$N$124,$B$2:$B$124,P24,$D$2:$D$124,"ABIERTA"))) -> ... | AC24: TRX | AD24: =IFERROR(__xludf.DUMMYFUNCTION("IFERROR(GOOGLEFINANCE(""CURRENCY:""&AC24&""USDT""),GECKOPRICE(AC24,""USD""))"),0.317713) -> 0.317713
A25: Binance | B25: SOL | C25: 45271 | D25: CERRADA | E25: 45282 | F25: =if(B25=0,"...", IF(E25=0,today()-C25,E25-C25)) -> 11 | G25: 0.27 | H25: 74.07 | I25: =IF(B25=0,"...",IF(D25="CERRADA","-",VLOOKUP(B25,$AC$2:$AD$27,2,FALSE))) -> - | J25: 97 | K25: =if(B25=0,"...",G25*H25) -> 19.9989 | L25: =IF(B25=0,"...",G25*J25) -> 26.19 | M25: =if(B25=0,"...",L25/K25-1) -> 0.30957203 | N25: =if(B25=0,"...",L25-K25) -> 6.1911 | P25: FET | Q25: =if(P25=0,"...",sumifs($G$2:$G$124,$B$2:$B$124,P25,$D$2:$D$124,"ABIERTA")) -> 0 | R25: =if(P25=0,"",T25/$Y$18) -> #ERROR! | S25: =if(Q25=0,"...",if(P25=0,"...",sumifs($K$2:$K$124,$B$2:$B$124,P25,$D$2:$D$124,"ABIERTA")/Q25)) -> ... | T25: =if(P25=0,"...",sumifs($L$2:$L$124,$B$2:$B$124,P25,$D$2:$D$124,"ABIERTA")) -> 0 | U25: =if(Q25=0,"...",if(P25=0,"...",V25/(T25-V25))) -> ... | V25: =if(Q25=0,"...",if(P25=0,"...",sumifs($N$2:$N$124,$B$2:$B$124,P25,$D$2:$D$124,"ABIERTA"))) -> ... | AC25: UNI | AD25: =IFERROR(__xludf.DUMMYFUNCTION("IFERROR(GOOGLEFINANCE(""CURRENCY:""&AC25&""USDT""),GECKOPRICE(AC25,""USD""))"),"#ERROR!") -> #ERROR!
A26: Binance | B26: MATIC | C26: 45271 | D26: CERRADA | F26: =if(B26=0,"...", IF(E26=0,today()-C26,E26-C26)) -> 846 | G26: 22.8 | H26: 0.88 | I26: =IF(B26=0,"...",IF(D26="CERRADA","-",VLOOKUP(B26,$AC$2:$AD$27,2,FALSE))) -> - | J26: 0.9 | K26: =if(B26=0,"...",G26*H26) -> 20.064 | L26: =IF(B26=0,"...",G26*J26) -> 20.52 | M26: =if(B26=0,"...",L26/K26-1) -> 0.022727273 | N26: =if(B26=0,"...",L26-K26) -> 0.456 | P26: ETH | Q26: =if(P26=0,"...",sumifs($G$2:$G$124,$B$2:$B$124,P26,$D$2:$D$124,"ABIERTA")) -> 0 | R26: =if(P26=0,"",T26/$Y$18) -> #ERROR! | S26: =if(Q26=0,"...",if(P26=0,"...",sumifs($K$2:$K$124,$B$2:$B$124,P26,$D$2:$D$124,"ABIERTA")/Q26)) -> ... | T26: =if(P26=0,"...",sumifs($L$2:$L$124,$B$2:$B$124,P26,$D$2:$D$124,"ABIERTA")) -> 0 | U26: =if(Q26=0,"...",if(P26=0,"...",V26/(T26-V26))) -> ... | V26: =if(Q26=0,"...",if(P26=0,"...",sumifs($N$2:$N$124,$B$2:$B$124,P26,$D$2:$D$124,"ABIERTA"))) -> ... | X26: Config Gráficas | Y26: Tipo | Z26: column | AC26: DOGE
A27: Binance | B27: BTC | C27: 45271 | D27: CERRADA | F27: =if(B27=0,"...", IF(E27=0,today()-C27,E27-C27)) -> 846 | G27: 0.0015 | H27: 42346.67 | I27: =IF(B27=0,"...",IF(D27="CERRADA","-",VLOOKUP(B27,$AC$2:$AD$27,2,FALSE))) -> - | J27: =IF(B27=0,"...",IF(D27="CERRADA","Valor Venta",I27*(1-VLOOKUP(A27,Config!$B$3:$C$22,2,FALSE)))) -> Valor Venta | K27: =if(B27=0,"...",G27*H27) -> 63.520005 | L27: =IF(B27=0,"...",G27*J27) -> #VALUE! | M27: =if(B27=0,"...",L27/K27-1) -> #VALUE! | N27: =if(B27=0,"...",L27-K27) -> #VALUE! | P27: BNB | Q27: =if(P27=0,"...",sumifs($G$2:$G$124,$B$2:$B$124,P27,$D$2:$D$124,"ABIERTA")) -> 0.08891975 | R27: =if(P27=0,"",T27/$Y$18) -> #ERROR! | S27: =if(Q27=0,"...",if(P27=0,"...",sumifs($K$2:$K$124,$B$2:$B$124,P27,$D$2:$D$124,"ABIERTA")/Q27)) -> 562.3 | T27: =if(P27=0,"...",sumifs($L$2:$L$124,$B$2:$B$124,P27,$D$2:$D$124,"ABIERTA")) -> 52.376591 | U27: =if(Q27=0,"...",if(P27=0,"...",V27/(T27-V27))) -> 0.047540721 | V27: =if(Q27=0,"...",if(P27=0,"...",sumifs($N$2:$N$124,$B$2:$B$124,P27,$D$2:$D$124,"ABIERTA"))) -> 2.3770158 | Y27: Días | Z27: 14 | AC27: SUI | AD27: =IFERROR(__xludf.DUMMYFUNCTION("IFERROR(GOOGLEFINANCE(""CURRENCY:""&AC27&""USDT""),GECKOPRICE(AC27,""USD""))"),0.850209) -> 0.850209
A28: Binance | B28: BTC | C28: 45267 | D28: CERRADA | F28: =if(B28=0,"...", IF(E28=0,today()-C28,E28-C28)) -> 850 | G28: 0.00138 | H28: 43289.86 | I28: =IF(B28=0,"...",IF(D28="CERRADA","-",VLOOKUP(B28,$AC$2:$AD$27,2,FALSE))) -> - | J28: =IF(B28=0,"...",IF(D28="CERRADA","Valor Venta",I28*(1-VLOOKUP(A28,Config!$B$3:$C$22,2,FALSE)))) -> Valor Venta | K28: =if(B28=0,"...",G28*H28) -> 59.740007 | L28: =IF(B28=0,"...",G28*J28) -> #VALUE! | M28: =if(B28=0,"...",L28/K28-1) -> #VALUE! | N28: =if(B28=0,"...",L28-K28) -> #VALUE! | P28: RAY | Q28: =if(P28=0,"...",sumifs($G$2:$G$124,$B$2:$B$124,P28,$D$2:$D$124,"ABIERTA")) -> 8.6 | R28: =if(P28=0,"",T28/$Y$18) -> #ERROR! | S28: =if(Q28=0,"...",if(P28=0,"...",sumifs($K$2:$K$124,$B$2:$B$124,P28,$D$2:$D$124,"ABIERTA")/Q28)) -> 5.769 | T28: =if(P28=0,"...",sumifs($L$2:$L$124,$B$2:$B$124,P28,$D$2:$D$124,"ABIERTA")) -> 5.10484 | U28: =if(Q28=0,"...",if(P28=0,"...",V28/(T28-V28))) -> -0.89710764 | V28: =if(Q28=0,"...",if(P28=0,"...",sumifs($N$2:$N$124,$B$2:$B$124,P28,$D$2:$D$124,"ABIERTA"))) -> -44.50856 | AC28: RAY | AD28: =IFERROR(__xludf.DUMMYFUNCTION("IFERROR(GOOGLEFINANCE(""CURRENCY:""&AC28&""USDT""),GECKOPRICE(AC28,""USD""))"),0.597927) -> 0.597927
A29: Binance | B29: BTC | C29: 45267 | D29: CERRADA | F29: =if(B29=0,"...", IF(E29=0,today()-C29,E29-C29)) -> 850 | G29: 0.00138 | H29: 43350 | I29: =IF(B29=0,"...",IF(D29="CERRADA","-",VLOOKUP(B29,$AC$2:$AD$27,2,FALSE))) -> - | J29: =IF(B29=0,"...",IF(D29="CERRADA","Valor Venta",I29*(1-VLOOKUP(A29,Config!$B$3:$C$22,2,FALSE)))) -> Valor Venta | K29: =if(B29=0,"...",G29*H29) -> 59.823 | L29: =IF(B29=0,"...",G29*J29) -> #VALUE! | M29: =if(B29=0,"...",L29/K29-1) -> #VALUE! | N29: =if(B29=0,"...",L29-K29) -> #VALUE! | P29: RONIN | Q29: =if(P29=0,"...",sumifs($G$2:$G$124,$B$2:$B$124,P29,$D$2:$D$124,"ABIERTA")) -> 0 | R29: =if(P29=0,"",T29/$Y$18) -> #ERROR! | S29: =if(Q29=0,"...",if(P29=0,"...",sumifs($K$2:$K$124,$B$2:$B$124,P29,$D$2:$D$124,"ABIERTA")/Q29)) -> ... | T29: =if(P29=0,"...",sumifs($L$2:$L$124,$B$2:$B$124,P29,$D$2:$D$124,"ABIERTA")) -> 0 | U29: =if(Q29=0,"...",if(P29=0,"...",V29/(T29-V29))) -> ... | V29: =if(Q29=0,"...",if(P29=0,"...",sumifs($N$2:$N$124,$B$2:$B$124,P29,$D$2:$D$124,"ABIERTA"))) -> ... | AC29: XRP | AD29: =IFERROR(__xludf.DUMMYFUNCTION("IFERROR(GOOGLEFINANCE(""CURRENCY:""&AC29&""USDT""),GECKOPRICE(AC29,""USD""))"),1.3) -> 1.3
A30: Binance | B30: SOL | C30: 45236 | D30: CERRADA | E30: 45246 | F30: =if(B30=0,"...", IF(E30=0,today()-C30,E30-C30)) -> 10 | G30: 0.49 | H30: 40.08 | I30: =IF(B30=0,"...",IF(D30="CERRADA","-",VLOOKUP(B30,$AC$2:$AD$27,2,FALSE))) -> - | J30: 58.25 | K30: =if(B30=0,"...",G30*H30) -> 19.6392 | L30: =IF(B30=0,"...",G30*J30) -> 28.5425 | M30: =if(B30=0,"...",L30/K30-1) -> 0.45334331 | N30: =if(B30=0,"...",L30-K30) -> 8.9033 | P30: ONE | Q30: =if(P30=0,"...",sumifs($G$2:$G$124,$B$2:$B$124,P30,$D$2:$D$124,"ABIERTA")) -> 0 | R30: =if(P30=0,"",T30/$Y$18) -> #ERROR! | S30: =if(Q30=0,"...",if(P30=0,"...",sumifs($K$2:$K$124,$B$2:$B$124,P30,$D$2:$D$124,"ABIERTA")/Q30)) -> ... | T30: =if(P30=0,"...",sumifs($L$2:$L$124,$B$2:$B$124,P30,$D$2:$D$124,"ABIERTA")) -> 0 | U30: =if(Q30=0,"...",if(P30=0,"...",V30/(T30-V30))) -> ... | V30: =if(Q30=0,"...",if(P30=0,"...",sumifs($N$2:$N$124,$B$2:$B$124,P30,$D$2:$D$124,"ABIERTA"))) -> ...
A31: Binance | B31: SOL | C31: 45204 | D31: CERRADA | E31: 45246 | F31: =if(B31=0,"...", IF(E31=0,today()-C31,E31-C31)) -> 42 | G31: 0.88 | H31: 22.73 | I31: =IF(B31=0,"...",IF(D31="CERRADA","-",VLOOKUP(B31,$AC$2:$AD$27,2,FALSE))) -> - | J31: 58.25 | K31: =if(B31=0,"...",G31*H31) -> 20.0024 | L31: =IF(B31=0,"...",G31*J31) -> 51.26 | M31: =if(B31=0,"...",L31/K31-1) -> 1.5626925 | N31: =if(B31=0,"...",L31-K31) -> 31.2576 | P31: TRUMP | Q31: =if(P31=0,"...",sumifs($G$2:$G$124,$B$2:$B$124,P31,$D$2:$D$124,"ABIERTA")) -> 0 | R31: =if(P31=0,"",T31/$Y$18) -> #ERROR! | S31: =if(Q31=0,"...",if(P31=0,"...",sumifs($K$2:$K$124,$B$2:$B$124,P31,$D$2:$D$124,"ABIERTA")/Q31)) -> ... | T31: =if(P31=0,"...",sumifs($L$2:$L$124,$B$2:$B$124,P31,$D$2:$D$124,"ABIERTA")) -> 0 | U31: =if(Q31=0,"...",if(P31=0,"...",V31/(T31-V31))) -> ... | V31: =if(Q31=0,"...",if(P31=0,"...",sumifs($N$2:$N$124,$B$2:$B$124,P31,$D$2:$D$124,"ABIERTA"))) -> ...
A32: Binance | B32: BTC | C32: 45246 | D32: CERRADA | E32: 45253 | F32: =if(B32=0,"...", IF(E32=0,today()-C32,E32-C32)) -> 7 | G32: 0.00195 | H32: 35815.38 | I32: =IF(B32=0,"...",IF(D32="CERRADA","-",VLOOKUP(B32,$AC$2:$AD$27,2,FALSE))) -> - | J32: 37400 | K32: =if(B32=0,"...",G32*H32) -> 69.839991 | L32: =IF(B32=0,"...",G32*J32) -> 72.93 | M32: =if(B32=0,"...",L32/K32-1) -> 0.044244121 | N32: =if(B32=0,"...",L32-K32) -> 3.090009 | P32: ONDO | Q32: =if(P32=0,"...",sumifs($G$2:$G$124,$B$2:$B$124,P32,$D$2:$D$124,"ABIERTA")) -> 0 | R32: =if(P32=0,"",T32/$Y$18) -> #ERROR! | S32: =if(Q32=0,"...",if(P32=0,"...",sumifs($K$2:$K$124,$B$2:$B$124,P32,$D$2:$D$124,"ABIERTA")/Q32)) -> ... | T32: =if(P32=0,"...",sumifs($L$2:$L$124,$B$2:$B$124,P32,$D$2:$D$124,"ABIERTA")) -> 0 | U32: =if(Q32=0,"...",if(P32=0,"...",V32/(T32-V32))) -> ... | V32: =if(Q32=0,"...",if(P32=0,"...",sumifs($N$2:$N$124,$B$2:$B$124,P32,$D$2:$D$124,"ABIERTA"))) -> ...
A33: Binance | B33: BTC | C33: 45251 | D33: CERRADA | E33: 45253 | F33: =if(B33=0,"...", IF(E33=0,today()-C33,E33-C33)) -> 2 | G33: 0.00047 | H33: 36063.83 | I33: =IF(B33=0,"...",IF(D33="CERRADA","-",VLOOKUP(B33,$AC$2:$AD$27,2,FALSE))) -> - | J33: 37400 | K33: =if(B33=0,"...",G33*H33) -> 16.95 | L33: =IF(B33=0,"...",G33*J33) -> 17.578 | M33: =if(B33=0,"...",L33/K33-1) -> 0.037050141 | N33: =if(B33=0,"...",L33-K33) -> 0.6279999 | P33: XRP | Q33: =if(P33=0,"...",sumifs($G$2:$G$124,$B$2:$B$124,P33,$D$2:$D$124,"ABIERTA")) -> 32 | R33: =if(P33=0,"",T33/$Y$18) -> #ERROR! | S33: =if(Q33=0,"...",if(P33=0,"...",sumifs($K$2:$K$124,$B$2:$B$124,P33,$D$2:$D$124,"ABIERTA")/Q33)) -> 3.2356 | T33: =if(P33=0,"...",sumifs($L$2:$L$124,$B$2:$B$124,P33,$D$2:$D$124,"ABIERTA")) -> 41.297984 | U33: =if(Q33=0,"...",if(P33=0,"...",V33/(T33-V33))) -> -0.60113673 | V33: =if(Q33=0,"...",if(P33=0,"...",sumifs($N$2:$N$124,$B$2:$B$124,P33,$D$2:$D$124,"ABIERTA"))) -> -62.241216
A34: Binance | B34: MATIC | C34: 45271 | D34: CERRADA | F34: =if(B34=0,"...", IF(E34=0,today()-C34,E34-C34)) -> 846 | G34: 23.2 | H34: 0.86 | I34: =IF(B34=0,"...",IF(D34="CERRADA","-",VLOOKUP(B34,$AC$2:$AD$27,2,FALSE))) -> - | J34: 0.9 | K34: =if(B34=0,"...",G34*H34) -> 19.952 | L34: =IF(B34=0,"...",G34*J34) -> 20.88 | M34: =if(B34=0,"...",L34/K34-1) -> 0.046511628 | N34: =if(B34=0,"...",L34-K34) -> 0.928 | P34: SUI | Q34: =if(P34=0,"...",sumifs($G$2:$G$124,$B$2:$B$124,P34,$D$2:$D$124,"ABIERTA")) -> 27.6 | R34: =if(P34=0,"",T34/$Y$18) -> #ERROR! | S34: =if(Q34=0,"...",if(P34=0,"...",sumifs($K$2:$K$124,$B$2:$B$124,P34,$D$2:$D$124,"ABIERTA")/Q34)) -> 3.9621 | T34: =if(P34=0,"...",sumifs($L$2:$L$124,$B$2:$B$124,P34,$D$2:$D$124,"ABIERTA")) -> 23.295407 | U34: =if(Q34=0,"...",if(P34=0,"...",V34/(T34-V34))) -> -0.78697244 | V34: =if(Q34=0,"...",if(P34=0,"...",sumifs($N$2:$N$124,$B$2:$B$124,P34,$D$2:$D$124,"ABIERTA"))) -> -86.058553
A35: Binance | B35: ADA | C35: 45271 | D35: CERRADA | F35: =if(B35=0,"...", IF(E35=0,today()-C35,E35-C35)) -> 846 | G35: 36.1 | H35: 0.55 | I35: =IF(B35=0,"...",IF(D35="CERRADA","-",VLOOKUP(B35,$AC$2:$AD$27,2,FALSE))) -> - | J35: 0.7614 | K35: =if(B35=0,"...",G35*H35) -> 19.855 | L35: =IF(B35=0,"...",G35*J35) -> 27.48654 | M35: =if(B35=0,"...",L35/K35-1) -> 0.38436364 | N35: =if(B35=0,"...",L35-K35) -> 7.63154 | Q35: =if(P35=0,"...",sumifs($G$2:$G$124,$B$2:$B$124,P35,$D$2:$D$124,"ABIERTA")) -> ... | R35: =if(P35=0,"",T35/$Y$18) | S35: =if(Q35=0,"...",if(P35=0,"...",sumifs($K$2:$K$124,$B$2:$B$124,P35,$D$2:$D$124,"ABIERTA")/Q35)) -> ... | T35: =if(P35=0,"...",sumifs($L$2:$L$124,$B$2:$B$124,P35,$D$2:$D$124,"ABIERTA")) -> ... | U35: =if(Q35=0,"...",if(P35=0,"...",V35/(T35-V35))) -> ... | V35: =if(Q35=0,"...",if(P35=0,"...",sumifs($N$2:$N$124,$B$2:$B$124,P35,$D$2:$D$124,"ABIERTA"))) -> ...
A36: Binance | B36: BTC | C36: 45277 | D36: CERRADA | F36: =if(B36=0,"...", IF(E36=0,today()-C36,E36-C36)) -> 840 | G36: 0.00122 | H36: 40983.61 | I36: =IF(B36=0,"...",IF(D36="CERRADA","-",VLOOKUP(B36,$AC$2:$AD$27,2,FALSE))) -> - | J36: =IF(B36=0,"...",IF(D36="CERRADA","Valor Venta",I36*(1-VLOOKUP(A36,Config!$B$3:$C$22,2,FALSE)))) -> Valor Venta | K36: =if(B36=0,"...",G36*H36) -> 50.000004 | L36: =IF(B36=0,"...",G36*J36) -> #VALUE! | M36: =if(B36=0,"...",L36/K36-1) -> #VALUE! | N36: =if(B36=0,"...",L36-K36) -> #VALUE! | P36: XRP | Q36: =if(P36=0,"...",sumifs($G$2:$G$124,$B$2:$B$124,P36,$D$2:$D$124,"ABIERTA")) -> 32 | R36: =if(P36=0,"",T36/$Y$18) -> #ERROR! | S36: =if(Q36=0,"...",if(P36=0,"...",sumifs($K$2:$K$124,$B$2:$B$124,P36,$D$2:$D$124,"ABIERTA")/Q36)) -> 3.2356 | T36: =if(P36=0,"...",sumifs($L$2:$L$124,$B$2:$B$124,P36,$D$2:$D$124,"ABIERTA")) -> 41.297984 | U36: =if(Q36=0,"...",if(P36=0,"...",V36/(T36-V36))) -> -0.60113673 | V36: =if(Q36=0,"...",if(P36=0,"...",sumifs($N$2:$N$124,$B$2:$B$124,P36,$D$2:$D$124,"ABIERTA"))) -> -62.241216
A37: Binance | B37: SOL | C37: 45278 | D37: CERRADA | E37: 45282 | F37: =if(B37=0,"...", IF(E37=0,today()-C37,E37-C37)) -> 4 | G37: 1.46 | H37: 68.49 | I37: =IF(B37=0,"...",IF(D37="CERRADA","-",VLOOKUP(B37,$AC$2:$AD$27,2,FALSE))) -> - | J37: 97 | K37: =if(B37=0,"...",G37*H37) -> 99.9954 | L37: =IF(B37=0,"...",G37*J37) -> 141.62 | M37: =if(B37=0,"...",L37/K37-1) -> 0.41626515 | N37: =if(B37=0,"...",L37-K37) -> 41.6246 | Q37: =if(P37=0,"...",sumifs($G$2:$G$124,$B$2:$B$124,P37,$D$2:$D$124,"ABIERTA")) -> ... | R37: =if(P37=0,"",T37/$Y$18) | S37: =if(Q37=0,"...",if(P37=0,"...",sumifs($K$2:$K$124,$B$2:$B$124,P37,$D$2:$D$124,"ABIERTA")/Q37)) -> ... | T37: =if(P37=0,"...",sumifs($L$2:$L$124,$B$2:$B$124,P37,$D$2:$D$124,"ABIERTA")) -> ... | U37: =if(Q37=0,"...",if(P37=0,"...",V37/(T37-V37))) -> ... | V37: =if(Q37=0,"...",if(P37=0,"...",sumifs($N$2:$N$124,$B$2:$B$124,P37,$D$2:$D$124,"ABIERTA"))) -> ...
A38: Binance | B38: BTC | C38: 45277 | D38: CERRADA | F38: =if(B38=0,"...", IF(E38=0,today()-C38,E38-C38)) -> 840 | G38: 0.0012 | H38: 41666.67 | I38: =IF(B38=0,"...",IF(D38="CERRADA","-",VLOOKUP(B38,$AC$2:$AD$27,2,FALSE))) -> - | J38: =IF(B38=0,"...",IF(D38="CERRADA","Valor Venta",I38*(1-VLOOKUP(A38,Config!$B$3:$C$22,2,FALSE)))) -> Valor Venta | K38: =if(B38=0,"...",G38*H38) -> 50.000004 | L38: =IF(B38=0,"...",G38*J38) -> #VALUE! | M38: =if(B38=0,"...",L38/K38-1) -> #VALUE! | N38: =if(B38=0,"...",L38-K38) -> #VALUE! | P38: SOL | Q38: =if(P38=0,"...",sumifs($G$2:$G$124,$B$2:$B$124,P38,$D$2:$D$124,"ABIERTA")) -> 9.646 | R38: =if(P38=0,"",T38/$Y$18) -> #ERROR! | S38: =if(Q38=0,"...",if(P38=0,"...",sumifs($K$2:$K$124,$B$2:$B$124,P38,$D$2:$D$124,"ABIERTA")/Q38)) -> 154.17525 | T38: =if(P38=0,"...",sumifs($L$2:$L$124,$B$2:$B$124,P38,$D$2:$D$124,"ABIERTA")) -> 764.22082 | U38: =if(Q38=0,"...",if(P38=0,"...",V38/(T38-V38))) -> -0.48612563 | V38: =if(Q38=0,"...",if(P38=0,"...",sumifs($N$2:$N$124,$B$2:$B$124,P38,$D$2:$D$124,"ABIERTA"))) -> -722.95361
A39: Binance | B39: MATIC | C39: 45279 | D39: CERRADA | F39: =if(B39=0,"...", IF(E39=0,today()-C39,E39-C39)) -> 838 | G39: 149.2 | H39: 0.79 | I39: =IF(B39=0,"...",IF(D39="CERRADA","-",VLOOKUP(B39,$AC$2:$AD$27,2,FALSE))) -> - | J39: 0.9 | K39: =if(B39=0,"...",G39*H39) -> 117.868 | L39: =IF(B39=0,"...",G39*J39) -> 134.28 | M39: =if(B39=0,"...",L39/K39-1) -> 0.13924051 | N39: =if(B39=0,"...",L39-K39) -> 16.412 | Q39: =if(P39=0,"...",sumifs($G$2:$G$124,$B$2:$B$124,P39,$D$2:$D$124,"ABIERTA")) -> ... | R39: =if(P39=0,"",T39/$Y$18) | S39: =if(Q39=0,"...",if(P39=0,"...",sumifs($K$2:$K$124,$B$2:$B$124,P39,$D$2:$D$124,"ABIERTA")/Q39)) -> ... | T39: =if(P39=0,"...",sumifs($L$2:$L$124,$B$2:$B$124,P39,$D$2:$D$124,"ABIERTA")) -> ... | U39: =if(Q39=0,"...",if(P39=0,"...",V39/(T39-V39))) -> ... | V39: =if(Q39=0,"...",if(P39=0,"...",sumifs($N$2:$N$124,$B$2:$B$124,P39,$D$2:$D$124,"ABIERTA"))) -> ...
A40: Binance | B40: SOL | C40: 45271 | D40: CERRADA | E40: 45282 | F40: =if(B40=0,"...", IF(E40=0,today()-C40,E40-C40)) -> 11 | G40: 0.28 | H40: 69.39 | I40: =IF(B40=0,"...",IF(D40="CERRADA","-",VLOOKUP(B40,$AC$2:$AD$27,2,FALSE))) -> - | J40: 97 | K40: =if(B40=0,"...",G40*H40) -> 19.4292 | L40: =IF(B40=0,"...",G40*J40) -> 27.16 | M40: =if(B40=0,"...",L40/K40-1) -> 0.39789595 | N40: =if(B40=0,"...",L40-K40) -> 7.7308 | Q40: =if(P40=0,"...",sumifs($G$2:$G$124,$B$2:$B$124,P40,$D$2:$D$124,"ABIERTA")) -> ... | R40: =if(P40=0,"",T40/$Y$18) | S40: =if(Q40=0,"...",if(P40=0,"...",sumifs($K$2:$K$124,$B$2:$B$124,P40,$D$2:$D$124,"ABIERTA")/Q40)) -> ... | T40: =if(P40=0,"...",sumifs($L$2:$L$124,$B$2:$B$124,P40,$D$2:$D$124,"ABIERTA")) -> ... | U40: =if(Q40=0,"...",if(P40=0,"...",V40/(T40-V40))) -> ... | V40: =if(Q40=0,"...",if(P40=0,"...",sumifs($N$2:$N$124,$B$2:$B$124,P40,$D$2:$D$124,"ABIERTA"))) -> ...
...

Sheet Estrategia michel saylor
A1: Fecha | C1: Dólares agregados
A2: 45740 | C2: 31
A3: 45742 | C3: 22
A4: 45744 | C4: 80
A5: 45745 | C5: 20
A6: 45746 | C6: 20
A7: 45747 | C7: 15
A8: Cierre | C8: 324.9 | D8: =SUM(C2:C7) -> 188 | E8: =C8-D8 -> 136.9
A10: 45749 | C10: 60
A11: 45750 | C11: 30
A12: 45750 | C12: 50
A13: 45751 | C13: 30
A14: 45752 | C14: 20
A15: 45753 | C15: 30
A16: 45753 | C16: 60
A17: 45754 | C17: 45
A18: 45755 | C18: 20
A19: 45755 | C19: 40
A20: 45756 | C20: 20
A21: Cierre | C21: 491 | D21: =SUM(C10:C20) -> 405 | E21: =C21-D21 -> 86
A23: 45757 | C23: 40
A24: 45758 | C24: 20
A25: Cierre | C25: 64.8
A27: 45759 | C27: 40
A28: cierre | C28: 41.2
A30: 13/04/0205 | C30: 30
A31: 45761 | C31: 20
A32: 45762 | C32: 20
A33: 45762 | C33: 40
A34: 45763 | C34: 40
A35: 45764 | C35: 30
A36: 45765 | C36: 20
A37: 45766 | C37: 20
A38: 45766 | C38: 20
A39: 45767 | C39: 40
A40: Cierre | C40: 325 | D40: =SUM(C30:C39) -> 280 | E40: =C40-D40 -> 45
A42: 45768 | C42: 30
A43: 45769 | C43: 30
A44: 45770 | C44: 30
A45: 45771 | C45: 20
...

Sheet Acciones ARG
A1: ID | B1: Ticker | C1: Gráfica | D1: Apertura | E1: Estado | F1: Cierre | G1: Dias | H1: Unidades | I1: Valor Compra | J1: Valor Actual | K1: Total Compra | L1: Total compra USD | M1: Valor Venta | N1: Total Venta | O1: Total Venta USD | P1: Gan Dia (%) | Q1: Gan Dia | R1: Ganancias (%) | S1: Ganancias Bruta (USD) | U1: Ticker | V1: Unidades | W1: % Cartera | X1: PPC | Y1: Total (Abierto) | Z1: Ganancias (%) | AA1: Ganancias Tot
A2: IOL | B2: GGAL | C2: =IFERROR(__xludf.DUMMYFUNCTION("if(B2=0,""..."", sparkline(query(GOOGLEFINANCE(B2,""price"",today()-$AE$27,today()),""select Col2"",0),{""charttype"",$AE$26}))"),"") | D2: 45569 | E2: CERRADA | G2: =if(B2=0,"...", IF(F2=0,today()-D2,F2-D2)) -> 548 | H2: 18 | I2: 5380 | J2: =IFERROR(__xludf.DUMMYFUNCTION("IF(B2=0,""..."",IF(E2=""CERRADA"",""-"",GOOGLEFINANCE(""BCBA:"" & B2)))"),"-") -> - | K2: =IF(B2=0,"...",$H$2*I2) -> 96840 | L2: =IF(B2=0,"...",K2/VLOOKUP($D2,CCL!$A$12:$B$828,2,0)) -> 78.992447 | M2: 6230 | N2: =IF(B2=0,"...",H2*M2) -> 112140 | O2: {=IF(B2=0,"...",IF(E2="ABIERTA",N2/CCL!$E$2,N2/ VLOOKUP(F2,{CCL!M:N;CCL!$P:$Q},2,FALSE)))} -> #N/A | P2: =IFERROR(__xludf.DUMMYFUNCTION("IF(B2=0,""..."",IF(E2=""CERRADA"",""-"",GOOGLEFINANCE(B2,""changepct"")/100))"),"-") -> - | Q2: =IFERROR(__xludf.DUMMYFUNCTION("IF(B2=0,""..."",IF(E2=""CERRADA"",""-"",GOOGLEFINANCE(B2,""change"")*H2))"),"-") -> - | R2: =IF(B2=0,"...",O2/L2-1) -> #N/A | S2: =IF(B2=0,"...",O2-L2) -> #N/A | U2: =IFERROR(__xludf.DUMMYFUNCTION("Unique(Filter(B2:B28,E2:E28=""ABIERTA""))"),"YPFD") -> YPFD | V2: =if(U2=0,"...",sumifs($H$2:$H$28,$B$2:$B$28,U2,$E$2:$E$28,"ABIERTA")) -> 13 | W2: =if(U2=0,"",Y2/$AD$18) -> 0.67300771 | X2: =if(V2=0,"...",if(U2=0,"...",sumifs($M$2:$M$28,$B$2:$B$28,U2,$E$2:$E$28,"ABIERTA")/V2)) -> 9998.7462 | Y2: =if(U2=0,"...",sumifs($N$2:$N$28,$B$2:$B$28,U2,$E$2:$E$28,"ABIERTA")) -> 844894.05 | Z2: =if(V2=0,"...",if(U2=0,"...",AA2/(Y2-AA2))) -> 0.00013330133 | AA2: =if(V2=0,"...",if(U2=0,"...",sumifs($S$2:$S$28,$B$2:$B$28,U2,$E$2:$E$28,"ABIERTA"))) -> 112.61049
A3: IOL | B3: PAMP | C3: =IFERROR(__xludf.DUMMYFUNCTION("if(B3=0,""..."", sparkline(query(GOOGLEFINANCE(B3,""price"",today()-$AE$27,today()),""select Col2"",0),{""charttype"",$AE$26}))"),"") | D3: 45595 | E3: CERRADA | G3: =if(B3=0,"...", IF(F3=0,today()-D3,F3-D3)) -> 522 | H3: 31 | I3: 3090 | J3: =IFERROR(__xludf.DUMMYFUNCTION("IF(B3=0,""..."",IF(E3=""CERRADA"",""-"",GOOGLEFINANCE(""BCBA:"" & B3)))"),"-") -> - | K3: =IF(B3=0,"...",H3*I3) -> 95790 | L3: =IF(B3=0,"...",K3/VLOOKUP($D3,CCL!$A$12:$B$828,2,0)) -> 82.677369 | M3: 3740 | N3: =IF(B3=0,"...",H3*M3) -> 115940 | O3: {=IF(B3=0,"...",IF(E3="ABIERTA",N3/CCL!$E$2,N3/ VLOOKUP(F3,{CCL!M:N;CCL!$P:$Q},2,FALSE)))} -> #N/A | P3: =IFERROR(__xludf.DUMMYFUNCTION("IF(B3=0,""..."",IF(E3=""CERRADA"",""-"",GOOGLEFINANCE(B3,""changepct"")/100))"),"-") -> - | Q3: =IFERROR(__xludf.DUMMYFUNCTION("IF(B3=0,""..."",IF(E3=""CERRADA"",""-"",GOOGLEFINANCE(B3,""change"")*H3))"),"-") -> - | R3: =IF(B3=0,"...",O3/L3-1) -> #N/A | S3: =IF(B3=0,"...",O3-L3) -> #N/A | U3: =IFERROR(__xludf.DUMMYFUNCTION("""COMPUTED_VALUE"""),"BCBA:GGAL") -> BCBA:GGAL | V3: =if(U3=0,"...",sumifs($H$2:$H$28,$B$2:$B$28,U3,$E$2:$E$28,"ABIERTA")) -> 60 | W3: =if(U3=0,"",Y3/$AD$18) -> 0.32699229 | X3: =if(V3=0,"...",if(U3=0,"...",sumifs($M$2:$M$28,$B$2:$B$28,U3,$E$2:$E$28,"ABIERTA")/V3)) -> 114.0295 | Y3: =if(U3=0,"...",sumifs($N$2:$N$28,$B$2:$B$28,U3,$E$2:$E$28,"ABIERTA")) -> 410506.2 | Z3: =if(V3=0,"...",if(U3=0,"...",AA3/(Y3-AA3))) -> -0.00011815538 | AA3: =if(V3=0,"...",if(U3=0,"...",sumifs($S$2:$S$28,$B$2:$B$28,U3,$E$2:$E$28,"ABIERTA"))) -> -48.509249
A4: IOL | B4: ALUA | C4: =IFERROR(__xludf.DUMMYFUNCTION("if(B4=0,""..."", sparkline(query(GOOGLEFINANCE(B4,""price"",today()-$AE$27,today()),""select Col2"",0),{""charttype"",$AE$26}))"),"") | D4: 45621 | E4: CERRADA | F4: 45714 | G4: =if(B4=0,"...", IF(F4=0,today()-D4,F4-D4)) -> 93 | H4: 159 | I4: 951 | J4: =IFERROR(__xludf.DUMMYFUNCTION("IF(B4=0,""..."",IF(E4=""CERRADA"",""-"",GOOGLEFINANCE(B4)))"),"-") -> - | K4: =IF(B4=0,"...",H4*I4) -> 151209 | L4: =IF(B4=0,"...",K4/VLOOKUP($D4,CCL!$A$12:$B$828,2,0)) -> 136.21083 | M4: 793 | N4: =IF(B4=0,"...",H4*M4) -> 126087 | O4: {=IF(B4=0,"...",IF(E4="ABIERTA",N4/CCL!$E$2,N4/ VLOOKUP(F4,{CCL!M:N;CCL!$P:$Q},2,FALSE)))} -> 103.35085 | P4: =IFERROR(__xludf.DUMMYFUNCTION("IF(B4=0,""..."",IF(E4=""CERRADA"",""-"",GOOGLEFINANCE(B4,""changepct"")/100))"),"-") -> - | Q4: =IFERROR(__xludf.DUMMYFUNCTION("IF(B4=0,""..."",IF(E4=""CERRADA"",""-"",GOOGLEFINANCE(B4,""change"")*H4))"),"-") -> - | R4: =IF(B4=0,"...",O4/L4-1) -> -0.24124352 | S4: =IF(B4=0,"...",O4-L4) -> -32.859979 | V4: =if(U4=0,"...",sumifs($H$2:$H$28,$B$2:$B$28,U4,$E$2:$E$28,"ABIERTA")) -> ... | W4: =if(U4=0,"",Y4/$AD$18) | X4: =if(V4=0,"...",if(U4=0,"...",sumifs($M$2:$M$28,$B$2:$B$28,U4,$E$2:$E$28,"ABIERTA")/V4)) -> ... | Y4: =if(U4=0,"...",sumifs($N$2:$N$28,$B$2:$B$28,U4,$E$2:$E$28,"ABIERTA")) -> ... | Z4: =if(V4=0,"...",if(U4=0,"...",AA4/(Y4-AA4))) -> ... | AA4: =if(V4=0,"...",if(U4=0,"...",sumifs($S$2:$S$28,$B$2:$B$28,U4,$E$2:$E$28,"ABIERTA"))) -> ...
A5: IOL | B5: BCBA:SUPV | C5: =IFERROR(__xludf.DUMMYFUNCTION("if(B5=0,""..."", sparkline(query(GOOGLEFINANCE(B5,""price"",today()-$AE$27,today()),""select Col2"",0),{""charttype"",$AE$26}))"),"") | D5: 45625 | E5: CERRADA | H5: 42 | I5: 2620 | J5: =IFERROR(__xludf.DUMMYFUNCTION("IF(B5=0,""..."",IF(E5=""CERRADA"",""-"",GOOGLEFINANCE(B5)))"),"-") -> - | K5: =IF(B5=0,"...",H5*I5) -> 110040 | L5: =IF(B5=0,"...",K5/VLOOKUP($D5,CCL!$A$12:$B$828,2,0)) -> 99.19501 | M5: 3420 | N5: =IF(B5=0,"...",H5*M5) -> 143640 | O5: {=IF(B5=0,"...",IF(E5="ABIERTA",N5/CCL!$E$2,N5/ VLOOKUP(F5,{CCL!M:N;CCL!$P:$Q},2,FALSE)))} -> #N/A | P5: =IFERROR(__xludf.DUMMYFUNCTION("IF(B5=0,""..."",IF(E5=""CERRADA"",""-"",GOOGLEFINANCE(B5,""changepct"")/100))"),"-") -> - | Q5: =IFERROR(__xludf.DUMMYFUNCTION("IF(B5=0,""..."",IF(E5=""CERRADA"",""-"",GOOGLEFINANCE(B5,""change"")*H5))"),"-") -> - | R5: =IF(B5=0,"...",O5/L5-1) -> #N/A | S5: =IF(B5=0,"...",O5-L5) -> #N/A | V5: =if(U5=0,"...",sumifs($H$2:$H$28,$B$2:$B$28,U5,$E$2:$E$28,"ABIERTA")) -> ... | W5: =if(U5=0,"",Y5/$AD$18) | X5: =if(V5=0,"...",if(U5=0,"...",sumifs($M$2:$M$28,$B$2:$B$28,U5,$E$2:$E$28,"ABIERTA")/V5)) -> ... | Y5: =if(U5=0,"...",sumifs($N$2:$N$28,$B$2:$B$28,U5,$E$2:$E$28,"ABIERTA")) -> ... | Z5: =if(V5=0,"...",if(U5=0,"...",AA5/(Y5-AA5))) -> ... | AA5: =if(V5=0,"...",if(U5=0,"...",sumifs($S$2:$S$28,$B$2:$B$28,U5,$E$2:$E$28,"ABIERTA"))) -> ...
A6: IOL | B6: BCBA:LOMA | C6: =IFERROR(__xludf.DUMMYFUNCTION("if(B6=0,""..."", sparkline(query(GOOGLEFINANCE(B6,""price"",today()-$AE$27,today()),""select Col2"",0),{""charttype"",$AE$26}))"),"") | D6: 45645 | E6: CERRADA | F6: 45695 | G6: =if(B6=0,"...", IF(F6=0,today()-D6,F6-D6)) -> 50 | H6: 50 | I6: 2795 | J6: =IFERROR(__xludf.DUMMYFUNCTION("IF(B6=0,""..."",IF(E6=""CERRADA"",""-"",GOOGLEFINANCE(B6)))"),"-") -> - | K6: =IF(B6=0,"...",H6*I6) -> 139750 | L6: =IF(B6=0,"...",K6/VLOOKUP($D6,CCL!$A$12:$B$828,2,0)) -> 120.72495 | M6: 2960 | N6: =IF(B6=0,"...",H6*M6) -> 148000 | O6: {=IF(B6=0,"...",IF(E6="ABIERTA",N6/CCL!$E$2,N6/ VLOOKUP(F6,{CCL!M:N;CCL!$P:$Q},2,FALSE)))} -> 123.00839 | P6: =IFERROR(__xludf.DUMMYFUNCTION("IF(B6=0,""..."",IF(E6=""CERRADA"",""-"",GOOGLEFINANCE(B6,""changepct"")/100))"),"-") -> - | Q6: =IFERROR(__xludf.DUMMYFUNCTION("IF(B6=0,""..."",IF(E6=""CERRADA"",""-"",GOOGLEFINANCE(B6,""change"")*H6))"),"-") -> - | R6: =IF(B6=0,"...",O6/L6-1) -> 0.018914331 | S6: =IF(B6=0,"...",O6-L6) -> 2.2834317 | V6: =if(U6=0,"...",sumifs($H$2:$H$28,$B$2:$B$28,U6,$E$2:$E$28,"ABIERTA")) -> ... | W6: =if(U6=0,"",Y6/$AD$18) | X6: =if(V6=0,"...",if(U6=0,"...",sumifs($M$2:$M$28,$B$2:$B$28,U6,$E$2:$E$28,"ABIERTA")/V6)) -> ... | Y6: =if(U6=0,"...",sumifs($N$2:$N$28,$B$2:$B$28,U6,$E$2:$E$28,"ABIERTA")) -> ... | Z6: =if(V6=0,"...",if(U6=0,"...",AA6/(Y6-AA6))) -> ... | AA6: =if(V6=0,"...",if(U6=0,"...",sumifs($S$2:$S$28,$B$2:$B$28,U6,$E$2:$E$28,"ABIERTA"))) -> ...
A7: IOL | B7: PAMP | C7: =IFERROR(__xludf.DUMMYFUNCTION("if(B7=0,""..."", sparkline(query(GOOGLEFINANCE(B7,""price"",today()-$AE$27,today()),""select Col2"",0),{""charttype"",$AE$26}))"),"") | D7: 45868 | E7: CERRADA | F7: 45961 | G7: =if(B7=0,"...", IF(F7=0,today()-D7,F7-D7)) -> 93 | H7: 41 | I7: 4070 | J7: =IFERROR(__xludf.DUMMYFUNCTION("IF(B7=0,""..."",IF(E7=""CERRADA"",""-"",GOOGLEFINANCE(B7)))"),"-") -> - | K7: =IF(B7=0,"...",H7*I7) -> 166870 | L7: {=IF($D7=0,"...",K7/VLOOKUP($D7,{CCL!M:N;CCL!$P:$Q},2,FALSE))} -> 126.41667 | M7: 5120 | N7: =IF(B7=0,"...",H7*M7) -> 209920 | O7: {=IF(B7=0,"...",IF(E7="ABIERTA",N7/CCL!$E$2,N7/ VLOOKUP(F7,{CCL!M:N;CCL!$P:$Q},2,FALSE)))} -> 139.34007 | P7: =IFERROR(__xludf.DUMMYFUNCTION("IF(B7=0,""..."",IF(E7=""CERRADA"",""-"",GOOGLEFINANCE(B7,""changepct"")/100))"),"-") -> - | Q7: =IFERROR(__xludf.DUMMYFUNCTION("IF(B7=0,""..."",IF(E7=""CERRADA"",""-"",GOOGLEFINANCE(B7,""change"")*H7))"),"-") -> - | R7: =IF(B7=0,"...",O7/L7-1) -> 0.10222866 | S7: =IF(B7=0,"...",O7-L7) -> 12.923406 | V7: =if(U7=0,"...",sumifs($H$2:$H$28,$B$2:$B$28,U7,$E$2:$E$28,"ABIERTA")) -> ... | W7: =if(U7=0,"",Y7/$AD$18) | X7: =if(V7=0,"...",if(U7=0,"...",sumifs($M$2:$M$28,$B$2:$B$28,U7,$E$2:$E$28,"ABIERTA")/V7)) -> ... | Y7: =if(U7=0,"...",sumifs($N$2:$N$28,$B$2:$B$28,U7,$E$2:$E$28,"ABIERTA")) -> ... | Z7: =if(V7=0,"...",if(U7=0,"...",AA7/(Y7-AA7))) -> ... | AA7: =if(V7=0,"...",if(U7=0,"...",sumifs($S$2:$S$28,$B$2:$B$28,U7,$E$2:$E$28,"ABIERTA"))) -> ...
A8: IOL | B8: YPFD | C8: =IFERROR(__xludf.DUMMYFUNCTION("if(B8=0,""..."", sparkline(query(GOOGLEFINANCE(B8,""price"",today()-$AE$27,today()),""select Col2"",0),{""charttype"",$AE$26}))"),"") | D8: 45868 | E8: ABIERTA | G8: =if(B8=0,"...", IF(F8=0,today()-D8,F8-D8)) -> 249 | H8: 4 | I8: 44375 | J8: =IFERROR(__xludf.DUMMYFUNCTION("IF(B8=0,""..."",IF(E8=""CERRADA"",""-"",GOOGLEFINANCE(B8)))"),65450.0) -> 65450 | K8: =IF(B8=0,"...",H8*I8) -> 177500 | L8: {=IF($D8=0,"...",K8/VLOOKUP($D8,{CCL!M:N;CCL!$P:$Q},2,FALSE))} -> 134.4697 | M8: =IF(B8=0,"...",IF(E8="CERRADA","Valor Venta",J8*(1-VLOOKUP(A8,Config!$B$3:$C$22,2,FALSE)))) -> 64991.85 | N8: =IF(B8=0,"...",H8*M8) -> 259967.4 | O8: {=IF(B8=0,"...",IF(E8="ABIERTA",N8/CCL!$E$2,N8/ VLOOKUP(F8,{CCL!M:N;CCL!$P:$Q},2,FALSE)))} -> 175.95682 | P8: =IFERROR(__xludf.DUMMYFUNCTION("IF(B8=0,""..."",IF(E8=""CERRADA"",""-"",GOOGLEFINANCE(B8,""changepct"")/100))"),-0.0304) -> -0.0304 | Q8: =IFERROR(__xludf.DUMMYFUNCTION("IF(B8=0,""..."",IF(E8=""CERRADA"",""-"",GOOGLEFINANCE(B8,""change"")*H8))"),-8200.0) -> -8200 | R8: =IF(B8=0,"...",O8/L8-1) -> 0.30852394 | S8: =IF(B8=0,"...",O8-L8) -> 41.487121 | V8: =if(U8=0,"...",sumifs($H$2:$H$28,$B$2:$B$28,U8,$E$2:$E$28,"ABIERTA")) -> ... | W8: =if(U8=0,"",Y8/$AD$18) | X8: =if(V8=0,"...",if(U8=0,"...",sumifs($M$2:$M$28,$B$2:$B$28,U8,$E$2:$E$28,"ABIERTA")/V8)) -> ... | Y8: =if(U8=0,"...",sumifs($N$2:$N$28,$B$2:$B$28,U8,$E$2:$E$28,"ABIERTA")) -> ... | Z8: =if(V8=0,"...",if(U8=0,"...",AA8/(Y8-AA8))) -> ... | AA8: =if(V8=0,"...",if(U8=0,"...",sumifs($S$2:$S$28,$B$2:$B$28,U8,$E$2:$E$28,"ABIERTA"))) -> ...
A9: IOL | B9: YPFD | C9: =IFERROR(__xludf.DUMMYFUNCTION("if(B9=0,""..."", sparkline(query(GOOGLEFINANCE(B9,""price"",today()-$AE$27,today()),""select Col2"",0),{""charttype"",$AE$26}))"),"") | D9: 46021 | E9: ABIERTA | G9: =if(B9=0,"...", IF(F9=0,today()-D9,F9-D9)) -> 96 | H9: 9 | I9: 54900 | J9: =IFERROR(__xludf.DUMMYFUNCTION("IF(B9=0,""..."",IF(E9=""CERRADA"",""-"",GOOGLEFINANCE(B9)))"),65450.0) -> 65450 | K9: =IF(B9=0,"...",H9*I9) -> 494100 | L9: {=IF($D9=0,"...",K9/VLOOKUP($D9,{CCL!M:N;CCL!$P:$Q},2,FALSE))} -> 324.77947 | M9: =IF(B9=0,"...",IF(E9="CERRADA","Valor Venta",J9*(1-VLOOKUP(A9,Config!$B$3:$C$22,2,FALSE)))) -> 64991.85 | N9: =IF(B9=0,"...",H9*M9) -> 584926.65 | O9: {=IF(B9=0,"...",IF(E9="ABIERTA",N9/CCL!$E$2,N9/ VLOOKUP(F9,{CCL!M:N;CCL!$P:$Q},2,FALSE)))} -> 395.90284 | P9: =IFERROR(__xludf.DUMMYFUNCTION("IF(B9=0,""..."",IF(E9=""CERRADA"",""-"",GOOGLEFINANCE(B9,""changepct"")/100))"),-0.0304) -> -0.0304 | Q9: =IFERROR(__xludf.DUMMYFUNCTION("IF(B9=0,""..."",IF(E9=""CERRADA"",""-"",GOOGLEFINANCE(B9,""change"")*H9))"),-18450.0) -> -18450 | R9: =IF(B9=0,"...",O9/L9-1) -> 0.21898973 | S9: =IF(B9=0,"...",O9-L9) -> 71.123369 | V9: =if(U9=0,"...",sumifs($H$2:$H$28,$B$2:$B$28,U9,$E$2:$E$28,"ABIERTA")) -> ... | W9: =if(U9=0,"",Y9/$AD$18) | X9: =if(V9=0,"...",if(U9=0,"...",sumifs($M$2:$M$28,$B$2:$B$28,U9,$E$2:$E$28,"ABIERTA")/V9)) -> ... | Y9: =if(U9=0,"...",sumifs($N$2:$N$28,$B$2:$B$28,U9,$E$2:$E$28,"ABIERTA")) -> ... | Z9: =if(V9=0,"...",if(U9=0,"...",AA9/(Y9-AA9))) -> ... | AA9: =if(V9=0,"...",if(U9=0,"...",sumifs($S$2:$S$28,$B$2:$B$28,U9,$E$2:$E$28,"ABIERTA"))) -> ...
A10: IOL | B10: BCBA:GGAL | C10: =IFERROR(__xludf.DUMMYFUNCTION("if(B10=0,""..."", sparkline(query(GOOGLEFINANCE(B10,""price"",today()-$AE$27,today()),""select Col2"",0),{""charttype"",$AE$26}))"),"") | D10: 46021 | E10: ABIERTA | G10: =IF(B10=0,"...", IF(F10=0,TODAY()-D10,F10-D10)) -> 96 | H10: 60 | I10: 8275 | J10: =IFERROR(__xludf.DUMMYFUNCTION("IF(B10=0,""..."",IF(E10=""CERRADA"",""-"",GOOGLEFINANCE(B10)))"),6890.0) -> 6890 | K10: =IF(B10=0,"...",H10*I10) -> 496500 | L10: {=IF($D10=0,"...",K10/VLOOKUP($D10,{CCL!M:N;CCL!$P:$Q},2,FALSE))} -> 326.35703 | M10: =IF(B10=0,"...",IF(E10="CERRADA","Valor Venta",J10*(1-VLOOKUP(A10,Config!$B$3:$C$22,2,FALSE)))) -> 6841.77 | N10: =IF(B10=0,"...",H10*M10) -> 410506.2 | O10: {=IF(B10=0,"...",IF(E10="ABIERTA",N10/CCL!$E$2,N10/ VLOOKUP(F10,{CCL!M:N;CCL!$P:$Q},2,FALSE)))} -> 277.84778 | P10: =IFERROR(__xludf.DUMMYFUNCTION("IF(B10=0,""..."",IF(E10=""CERRADA"",""-"",GOOGLEFINANCE(B10,""changepct"")/100))"),0.0) -> 0 | Q10: =IFERROR(__xludf.DUMMYFUNCTION("IF(B10=0,""..."",IF(E10=""CERRADA"",""-"",GOOGLEFINANCE(B10,""change"")*H10))"),0.0) -> 0 | R10: =IF(B10=0,"...",O10/L10-1) -> -0.14863859 | S10: =IF(B10=0,"...",O10-L10) -> -48.509249 | V10: =if(U10=0,"...",sumifs($H$2:$H$28,$B$2:$B$28,U10,$E$2:$E$28,"ABIERTA")) -> ... | W10: =if(U10=0,"",Y10/$AD$18) | X10: =if(V10=0,"...",if(U10=0,"...",sumifs($M$2:$M$28,$B$2:$B$28,U10,$E$2:$E$28,"ABIERTA")/V10)) -> ... | Y10: =if(U10=0,"...",sumifs($N$2:$N$28,$B$2:$B$28,U10,$E$2:$E$28,"ABIERTA")) -> ... | Z10: =if(V10=0,"...",if(U10=0,"...",AA10/(Y10-AA10))) -> ... | AA10: =if(V10=0,"...",if(U10=0,"...",sumifs($S$2:$S$28,$B$2:$B$28,U10,$E$2:$E$28,"ABIERTA"))) -> ...
C11: =IFERROR(__xludf.DUMMYFUNCTION("if(B11=0,""..."", sparkline(query(GOOGLEFINANCE(B11,""price"",today()-$AE$27,today()),""select Col2"",0),{""charttype"",$AE$26}))"),"...") -> ... | G11: =if(B11=0,"...", IF(F11=0,today()-D11,F11-D11)) -> ... | J11: =IFERROR(__xludf.DUMMYFUNCTION("IF(B11=0,""..."",IF(E11=""CERRADA"",""-"",GOOGLEFINANCE(B11)*100))"),"...") -> ... | K11: =IF(B11=0,"...",H11*I11) -> ... | L11: =IF(B11=0,"...",K11/VLOOKUP($D11,CCL!$A$12:$B$828,2,0)) -> ... | M11: =IF(B11=0,"...",IF(E11="CERRADA","Valor Venta",J11*(1-VLOOKUP($A$2,Config!$B$3:$C$22,2,FALSE)))) -> ... | N11: =IF(B11=0,"...",H11*M11) -> ... | O11: {=IF(B11=0,"...",IF(E11="ABIERTA",K11/CCL!$E$2,N11/ VLOOKUP(F11,{CCL!M:N;CCL!$P:$Q},2,FALSE)))} -> ... | P11: =IFERROR(__xludf.DUMMYFUNCTION("if(B11=0,""..."",GOOGLEFINANCE(B11,""changepct"")/100)"),"...") -> ... | Q11: =IFERROR(__xludf.DUMMYFUNCTION("IF(B11=0,""..."",IF(E11=""CERRADA"",""-"",GOOGLEFINANCE(B11,""change"")*H11))"),"...") -> ... | R11: =IF(B11=0,"...",O11/L11-1) -> ... | S11: =IF(B11=0,"...",N11-K11) -> ... | V11: =if(U11=0,"...",sumifs($H$2:$H$28,$B$2:$B$28,U11,$E$2:$E$28,"ABIERTA")) -> ... | W11: =if(U11=0,"",Y11/$AD$18) | X11: =if(V11=0,"...",if(U11=0,"...",sumifs($M$2:$M$28,$B$2:$B$28,U11,$E$2:$E$28,"ABIERTA")/V11)) -> ... | Y11: =if(U11=0,"...",sumifs($N$2:$N$28,$B$2:$B$28,U11,$E$2:$E$28,"ABIERTA")) -> ... | Z11: =if(V11=0,"...",if(U11=0,"...",AA11/(Y11-AA11))) -> ... | AA11: =if(V11=0,"...",if(U11=0,"...",sumifs($S$2:$S$28,$B$2:$B$28,U11,$E$2:$E$28,"ABIERTA"))) -> ...
C12: =IFERROR(__xludf.DUMMYFUNCTION("if(B12=0,""..."", sparkline(query(GOOGLEFINANCE(B12,""price"",today()-$AE$27,today()),""select Col2"",0),{""charttype"",$AE$26}))"),"...") -> ... | G12: =if(B12=0,"...", IF(F12=0,today()-D12,F12-D12)) -> ... | J12: =IFERROR(__xludf.DUMMYFUNCTION("IF(B12=0,""..."",IF(E12=""CERRADA"",""-"",GOOGLEFINANCE(B12)))"),"...") -> ... | K12: =IF(B12=0,"...",H12*I12) -> ... | L12: =IF(B12=0,"...",K12/VLOOKUP($D12,CCL!$A$12:$B$828,2,0)) -> ... | M12: =IF(B12=0,"...",IF(E12="CERRADA","Valor Venta",J12*(1-VLOOKUP($A$2,Config!$B$3:$C$22,2,FALSE)))) -> ... | N12: =IF(B12=0,"...",H12*M12) -> ... | O12: {=IF(B12=0,"...",IF(E12="ABIERTA",K12/CCL!$E$2,N12/ VLOOKUP(F12,{CCL!M:N;CCL!$P:$Q},2,FALSE)))} -> ... | P12: =IFERROR(__xludf.DUMMYFUNCTION("if(B12=0,""..."",GOOGLEFINANCE(B12,""changepct"")/100)"),"...") -> ... | Q12: =IFERROR(__xludf.DUMMYFUNCTION("IF(B12=0,""..."",IF(E12=""CERRADA"",""-"",GOOGLEFINANCE(B12,""change"")*H12))"),"...") -> ... | R12: =IF(B12=0,"...",O12/L12-1) -> ... | S12: =IF(B12=0,"...",N12-K12) -> ... | V12: =if(U12=0,"...",sumifs($H$2:$H$28,$B$2:$B$28,U12,$E$2:$E$28,"ABIERTA")) -> ... | W12: =if(U12=0,"",Y12/$AD$18) | X12: =if(V12=0,"...",if(U12=0,"...",sumifs($M$2:$M$28,$B$2:$B$28,U12,$E$2:$E$28,"ABIERTA")/V12)) -> ... | Y12: =if(U12=0,"...",sumifs($N$2:$N$28,$B$2:$B$28,U12,$E$2:$E$28,"ABIERTA")) -> ... | Z12: =if(V12=0,"...",if(U12=0,"...",AA12/(Y12-AA12))) -> ... | AA12: =if(V12=0,"...",if(U12=0,"...",sumifs($S$2:$S$28,$B$2:$B$28,U12,$E$2:$E$28,"ABIERTA"))) -> ...
